Workbook

Sheet Informe 2025
C3: Resumen Anual de FORMACIÓN: 2025
S4: EURO ABRIL | T4: 1074.15
A5: N° | B5: Mes | C5: Título capacitación | D5: Lugar de impartición | E5: Fecha inicio | F5: Fecha fin | G5: Objetivo / Area temática | H5: Externo / Interno | I5: Tipo de curso | J5: Gerencia | K5: Formador / Proveedor | L5: Asistentes | M5: Horas | N5: Horas totales | O5: Coste total | P5: Valoracion del formador | Q5: Indice de satisfacciOn | R5: NPS
A6: 1 | B6: MARZO | C6: Introducción al mundo de la cocteleria | D6: PRESENCIAL | E6: 45729 | F6: 45729 | G6: CLIENTE | H6: INTERNO | I6: PRESENCIAL | J6: ARICA | K6: Oscar Ossandon | L6: 6 | M6: 2 | N6: =L6*M6 -> 12 | O6: 0 | P6: 0
A7: 2 | B7: MARZO | C7: Secuencia de servicio | D7: PRESENCIAL | E7: 45722 | F7: 45722 | G7: CLIENTE | H7: INTERNO | I7: PRESENCIAL | J7: ARICA | K7: Oscar Ossandon | L7: 5 | M7: 2 | N7: =L7*M7 -> 10 | O7: 0 | P7: 0
A8: 3 | B8: MARZO | C8: Introducción al mundo del vino | D8: PRESENCIAL | E8: 45726 | F8: 45726 | G8: CLIENTE | H8: INTERNO | I8: PRESENCIAL | J8: ARICA | K8: Oscar Ossandon | L8: 5 | M8: 2 | N8: =L8*M8 -> 10 | O8: 0 | P8: 0
A9: 4 | B9: MARZO | C9: Procedimiento Stock de cigarros | D9: PRESENCIAL | E9: 45722 | F9: 45722 | G9: Negocio | H9: INTERNO | I9: PRESENCIAL | J9: ARICA | K9: Alejandro Solis | L9: 6 | M9: 0.5 | N9: =L9*M9 -> 3 | O9: 0 | P9: 0
A10: 5 | B10: MARZO | C10: Reinducción indefinidos | D10: PRESENCIAL | E10: 45735 | F10: 45735 | G10: Negocio | H10: INTERNO | I10: PRESENCIAL | J10: ARICA | K10: RR.HH | L10: 11 | M10: 2 | N10: =L10*M10 -> 22 | O10: 0 | P10: 0
A11: 6 | B11: MARZO | C11: Curso excel básico | D11: PRESENCIAL | E11: 45740 | F11: 45740 | G11: Negocio | H11: INTERNO | I11: PRESENCIAL | J11: ARICA | K11: Leonel Herrera | L11: 19 | M11: 5 | N11: =L11*M11 -> 95 | O11: 0 | P11: 0
A12: 7 | B12: MARZO | C12: Programa Tutor | D12: PRESENCIAL | E12: 45736 | F12: 45736 | G12: Negocio | H12: INTERNO | I12: PRESENCIAL | J12: ARICA | K12: RR.HH | L12: 15 | M12: 2 | N12: =L12*M12 -> 30 | O12: 0 | P12: 0
A13: 8 | B13: MARZO | C13: Programa Tutor/Inclusion laboral | D13: PRESENCIAL | E13: 45743 | F13: 45743 | G13: Negocio | H13: INTERNO | I13: PRESENCIAL | J13: ARICA | K13: Nicole Urrutia | L13: 14 | M13: 2 | N13: =L13*M13 -> 28 | O13: 0 | P13: 0
A14: 9 | B14: MARZO | C14: Cata de Vinos | D14: PRESENCIAL | E14: 45723 | F14: 45723 | G14: CLIENTE | H14: INTERNO | I14: PRESENCIAL | J14: ARICA | L14: 24 | M14: 1.5 | N14: =L14*M14 -> 36 | O14: 0 | P14: 0
A15: 10 | B15: ABRIL | C15: Escuela CCTV | D15: PRESENCIAL | E15: 45768 | F15: 45779 | G15: Negocio | H15: INTERNO | I15: PRESENCIAL | J15: ARICA | K15: José Arias | L15: 3 | M15: 80 | N15: =L15*M15 -> 240 | O15: 0 | P15: 0
A16: 11 | B16: ABRIL | C16: Formación AA&BB | D16: PRESENCIAL | E16: 45750 | F16: 45750 | G16: Negocio | H16: INTERNO | I16: PRESENCIAL | J16: ARICA | K16: Alvaro Gatica | L16: 5 | M16: 2 | N16: =L16*M16 -> 10 | O16: 0 | P16: 0
A17: 12 | B17: ABRIL | C17: Tutor "capcula de seguridad" | D17: PRESENCIAL | E17: 45750 | F17: 45750 | G17: Negocio | H17: INTERNO | I17: PRESENCIAL | J17: ARICA | K17: Adan Carrasco | L17: 17 | M17: 2 | N17: =L17*M17 -> 34 | O17: 0 | P17: 0
A18: 13 | B18: ABRIL | C18: Introduccion al mundo de los destilados | D18: PRESENCIAL | E18: 45754 | F18: 45754 | G18: Negocio | H18: INTERNO | I18: PRESENCIAL | J18: ARICA | K18: Alvaro Gatica | L18: 2 | M18: 1 | N18: =L18*M18 -> 2 | O18: 0 | P18: 0
A19: 14 | B19: ABRIL | C19: Curso de Ingles | D19: PRESENCIAL | E19: 45754 | F19: 45754 | G19: Negocio | H19: Externo / Interno | I19: PRESENCIAL | J19: ARICA | K19: Anglosaxon | L19: 10 | M19: 12 | N19: =L19*M19 -> 120 | O19: =75000/T4 -> 69.82265 | P19: 0
A20: 15 | B20: ABRIL | C20: Charla concientización sobre la discapacidad | D20: PRESENCIAL | E20: 45756 | F20: 45756 | G20: Negocio | H20: Externo / Interno | I20: PRESENCIAL | J20: ARICA | K20: Fundación Impulso | L20: 37 | M20: 2 | N20: =L20*M20 -> 74 | O20: 0 | P20: 0
A21: 16 | B21: ABRIL | C21: Tutor "capsula servicio e imagen" | D21: PRESENCIAL | E21: 45757 | F21: 45757 | G21: Negocio | H21: INTERNO | I21: PRESENCIAL | J21: ARICA | K21: Leandro Torres | L21: 17 | M21: 2 | N21: =L21*M21 -> 34 | O21: 0 | P21: 0
A22: 17 | B22: ABRIL | C22: Servicio al cliente | D22: PRESENCIAL | E22: 45758 | F22: 45758 | G22: Negocio | H22: INTERNO | I22: PRESENCIAL | J22: ARICA | K22: Alvaro Gatica | L22: 5 | M22: 2 | N22: =L22*M22 -> 10 | O22: 0 | P22: 0
A23: 18 | B23: ABRIL | C23: Curso Lengua de Señas | D23: PRESENCIAL | E23: 45761 | F23: 45761 | G23: Negocio | H23: INTERNO | I23: PRESENCIAL | J23: ARICA | K23: Fundacion Impulso | L23: 35 | M23: 12 | N23: =L23*M23 -> 420 | O23: 0 | P23: 0
A24: 19 | B24: ABRIL | C24: Reentrenamiento Tutor | D24: PRESENCIAL | E24: 45762 | F24: 45762 | G24: Negocio | H24: INTERNO | I24: PRESENCIAL | J24: ARICA | K24: RR.HH | L24: 17 | M24: 6 | N24: =L24*M24 -> 102 | O24: 0 | P24: 0
A25: 20 | B25: ABRIL | C25: Primeros Auxilio | D25: PRESENCIAL | E25: 45764 | F25: 45764 | G25: Negocio | H25: Externo / Interno | I25: PRESENCIAL | J25: ARICA | K25: Achs | L25: 25 | M25: 3 | N25: =L25*M25 -> 75 | O25: 0 | P25: 0
A26: 21 | B26: ABRIL | C26: Primeros Auxilio | D26: PRESENCIAL | E26: 45768 | F26: 45768 | G26: Negocio | H26: Externo / Interno | I26: PRESENCIAL | J26: ARICA | K26: Achs | L26: 17 | M26: 3 | N26: =L26*M26 -> 51 | O26: 0 | P26: 0
A27: 22 | B27: ABRIL | C27: Decalogo del Buen trato | D27: PRESENCIAL | E27: 45773 | F27: 45773 | G27: Negocio | H27: Externo / Interno | I27: PRESENCIAL | J27: ARICA | K27: Alvaro Gatica | L27: 3 | M27: 2 | N27: =L27*M27 -> 6 | O27: 0 | P27: 0
A28: 23 | B28: ABRIL | C28: Transtorno Espectro Autista con enfoque de derechos | D28: PRESENCIAL | E28: 45775 | F28: 45776 | G28: Negocio | H28: Externo / Interno | I28: PRESENCIAL | J28: ARICA | K28: Fundación impulso | L28: 20 | M28: 8 | N28: =L28*M28 -> 160 | O28: =+(22000*20)/T4 -> 409.62622 | P28: 0
A29: 24 | B29: ABRIL | C29: Capacitaciones Parrilladas | D29: PRESENCIAL | E29: 45744 | F29: 45744 | G29: Negocio | H29: Externo / Interno | I29: PRESENCIAL | J29: ARICA | K29: Asociación de parrilleros Peru | L29: 2 | M29: 8 | N29: =L29*M29 -> 16 | O29: =230000/T4 -> 214.12279 | P29: 0
A30: 25 | B30: ABRIL | C30: Capacitación Cocina Moderna y Emplatados | D30: PRESENCIAL | E30: 45773 | F30: 45774 | G30: Negocio | H30: Externo / Interno | I30: PRESENCIAL | J30: ARICA | K30: Academia Gastronomica Internacional | L30: 3 | M30: 16 | N30: =L30*M30 -> 48 | O30: =+(300000+160000)/T4 -> 428.24559 | P30: 0
A31: 26 | B31: ABRIL | C31: Capacitacion maquinaria de Cocina | D31: PRESENCIAL | E31: 45771 | F31: 45771 | G31: Negocio | H31: Externo / Interno | I31: PRESENCIAL | J31: ARICA | K31: Marsol | L31: 6 | M31: 6 | N31: =L31*M31 -> 36 | O31: =420000/T4 -> 391.00684 | P31: 0
A32: 27 | B32: MAYO | C32: Charla concientización sobre la discapacidad | D32: PRESENCIAL | E32: 45799 | F32: 45799 | G32: Negocio | H32: Externo / Interno | I32: PRESENCIAL | J32: ARICA | K32: Fundacion Impulso | L32: 25 | M32: 2 | N32: =L32*M32 -> 50 | O32: 0 | P32: 0
A33: 28 | B33: MAYO | C33: Difusión Politica de Inclusión | D33: PRESENCIAL | E33: 45800 | F33: 45800 | G33: Negocio | H33: Externo / Interno | I33: PRESENCIAL | J33: ARICA | K33: Paola Cortés | L33: =44+25 -> 69 | M33: 1 | N33: =L33*M33 -> 69 | O33: 0 | P33: 0
A34: 29 | B34: MAYO | C34: Introduccion al mundo del café | D34: PRESENCIAL | E34: 45799 | F34: 45799 | G34: Negocio | H34: Externo / Interno | I34: PRESENCIAL | J34: ARICA | K34: Britt | L34: 6 | M34: 1 | N34: =L34*M34 -> 6 | O34: 0 | P34: 0
A35: 30 | B35: MAYO | C35: Induccion Indefinidos | D35: PRESENCIAL | E35: 45803 | F35: 45803 | G35: Negocio | H35: Externo / Interno | I35: PRESENCIAL | J35: ARICA | K35: Paola Cortés | L35: 8 | M35: 2 | N35: =L35*M35 -> 16 | O35: 0 | P35: 0
A36: 31 | B36: MAYO | C36: Imagen y servicio | D36: PRESENCIAL | E36: 45804 | F36: 45804 | G36: Negocio | H36: Externo / Interno | I36: PRESENCIAL | J36: ARICA | K36: Leandro Torres | L36: 19 | M36: 1.5 | N36: =L36*M36 -> 28.5 | O36: 0 | P36: 0
A37: 32 | B37: MAYO | C37: Capsula de prevencion de riesgo | D37: PRESENCIAL | E37: 45792 | F37: 45792 | G37: Negocio | H37: Externo / Interno | I37: PRESENCIAL | J37: ARICA | K37: Emma Vasquez | L37: 10 | M37: 1 | N37: =L37*M37 -> 10 | O37: 0 | P37: 0
A38: 33 | B38: MAYO | C38: Cierre Programa Tutor | D38: PRESENCIAL | E38: 45806 | F38: 45796 | G38: Negocio | H38: Externo / Interno | I38: PRESENCIAL | J38: ARICA | K38: Paola Cortés | L38: 26 | M38: 1 | N38: =L38*M38 -> 26 | O38: 0 | P38: 0
A39: 34 | B39: MAYO | C39: Gestion de Calidad y BPM | D39: PRESENCIAL | E39: 45785 | F39: 45785 | G39: Negocio | H39: Externo / Interno | I39: PRESENCIAL | J39: ARICA | K39: Johann Miranda | L39: 13 | M39: 1.5 | N39: =L39*M39 -> 19.5 | O39: 0 | P39: 0
A40: 35 | B40: MAYO | C40: Habilidades Blandas | D40: PRESENCIAL | E40: 45799 | F40: 45799 | G40: Negocio | H40: Externo / Interno | I40: PRESENCIAL | J40: ARICA | K40: Javiera Rivera | L40: 14 | M40: 1.5 | N40: =L40*M40 -> 21 | O40: 0 | P40: 0
A41: 36 | B41: MAYO | C41: Diplomado Marketing Digital | D41: ONLINE | E41: 45778 | F41: 45808 | G41: Negocio | H41: Externo / Interno | I41: ONLINE | J41: ARICA | K41: Universidad de Valparaiso | L41: 1 | M41: 100 | N41: =L41*M41 -> 100 | O41: =100000/T4 -> 93.096867 | P41: 0
A42: 37 | B42: MAYO | C42: Edición de video | D42: ONLINE | E42: 45778 | F42: 45808 | G42: Negocio | H42: Externo / Interno | I42: ONLINE | J42: ARICA | K42: Instituto Audiovisual | L42: 2 | M42: =36/3 -> 12 | N42: =L42*M42 -> 24 | O42: =(165000/3)/T4 -> 51.203277 | P42: 0
...

Sheet Participantes
A1: N° | B1: MES | C1: Rut | D1: NºEMPLEADO | E1: NOMBRE | F1: APELLIDOS | G1: CORREO | H1: NOMBRE CURSO | I1: TOTAL HRS FORMACION
A2: 1 | B2: =VLOOKUP(A2,'Informe 2025'!$1:$1048576,2,FALSE) -> MARZO | C2: 21149296-1 | D2: =VLOOKUP(C2,ID!$1:$1048576,4,FALSE) -> 103963 | E2: =VLOOKUP(C2,ID!$1:$1048576,3,FALSE) -> YEREZIM DIANA | F2: =VLOOKUP(C2,ID!$1:$1048576,2,FALSE) -> JIMENEZ HIDALGO | G2: =VLOOKUP(D2,CORREOS!$A$2:$B$570,2,FALSE) -> YHURTADO@antayhoteles.cl | H2: =VLOOKUP(A2,'Informe 2025'!$A$5:$C$164,3,FALSE) -> Introducción al mundo de la cocteleria | I2: 2
A3: 1 | B3: =VLOOKUP(A3,'Informe 2025'!$1:$1048576,2,FALSE) -> MARZO | C3: 21353679-6 | D3: =VLOOKUP(C3,ID!$1:$1048576,4,FALSE) -> 103252 | E3: =VLOOKUP(C3,ID!$1:$1048576,3,FALSE) -> DIEGO ADRIAN | F3: =VLOOKUP(C3,ID!$1:$1048576,2,FALSE) -> BARREAU FLORES | G3: =VLOOKUP(D3,CORREOS!$A$2:$B$570,2,FALSE) -> DBARREAU@antayhoteles.cl | H3: =VLOOKUP(A3,'Informe 2025'!$A$5:$C$164,3,FALSE) -> Introducción al mundo de la cocteleria | I3: 2
A4: 1 | B4: =VLOOKUP(A4,'Informe 2025'!$1:$1048576,2,FALSE) -> MARZO | C4: 25438930-7 | D4: =VLOOKUP(C4,ID!$1:$1048576,4,FALSE) -> 103965 | E4: =VLOOKUP(C4,ID!$1:$1048576,3,FALSE) -> YIRLEY YURANI | F4: =VLOOKUP(C4,ID!$1:$1048576,2,FALSE) -> HURTADO PRADO | G4: =VLOOKUP(D4,CORREOS!$A$2:$B$570,2,FALSE) -> YJHIDALGO@antayhoteles.cl | H4: =VLOOKUP(A4,'Informe 2025'!$A$5:$C$164,3,FALSE) -> Introducción al mundo de la cocteleria | I4: 2
A5: 1 | B5: =VLOOKUP(A5,'Informe 2025'!$1:$1048576,2,FALSE) -> MARZO | C5: 17555090-9 | D5: =VLOOKUP(C5,ID!$1:$1048576,4,FALSE) -> 102642 | E5: =VLOOKUP(C5,ID!$1:$1048576,3,FALSE) -> JOSE LUIS | F5: =VLOOKUP(C5,ID!$1:$1048576,2,FALSE) -> JIMENEZ VILLALOBOS | G5: =VLOOKUP(D5,CORREOS!$A$2:$B$570,2,FALSE) -> JJVILLALOBOS@ANTAYHOTELES.CL | H5: =VLOOKUP(A5,'Informe 2025'!$A$5:$C$164,3,FALSE) -> Introducción al mundo de la cocteleria | I5: =VLOOKUP(H5,'Informe 2025'!$C$6:$M$166,11,FALSE) -> 2
A6: 1 | B6: =VLOOKUP(A6,'Informe 2025'!$1:$1048576,2,FALSE) -> MARZO | C6: 22538546-7 | D6: =VLOOKUP(C6,ID!$1:$1048576,4,FALSE) -> 102982 | E6: =VLOOKUP(C6,ID!$1:$1048576,3,FALSE) -> CELINA | F6: =VLOOKUP(C6,ID!$1:$1048576,2,FALSE) -> GOMEZ OJEDA | G6: =VLOOKUP(D6,CORREOS!$A$2:$B$570,2,FALSE) -> CGOJEDA@ANTAYHOTELES.CL | H6: =VLOOKUP(A6,'Informe 2025'!$A$5:$C$164,3,FALSE) -> Introducción al mundo de la cocteleria | I6: =VLOOKUP(H6,'Informe 2025'!$C$6:$M$166,11,FALSE) -> 2
A7: 2 | B7: =VLOOKUP(A7,'Informe 2025'!$1:$1048576,2,FALSE) -> MARZO | C7: 21353679-6 | D7: =VLOOKUP(C7,ID!$1:$1048576,4,FALSE) -> 103252 | E7: =VLOOKUP(C7,ID!$1:$1048576,3,FALSE) -> DIEGO ADRIAN | F7: =VLOOKUP(C7,ID!$1:$1048576,2,FALSE) -> BARREAU FLORES | G7: =VLOOKUP(D7,CORREOS!$A$2:$B$570,2,FALSE) -> DBARREAU@antayhoteles.cl | H7: =VLOOKUP(A7,'Informe 2025'!$A$5:$C$164,3,FALSE) -> Secuencia de servicio | I7: =VLOOKUP(H7,'Informe 2025'!$C$6:$M$166,11,FALSE) -> 2
A8: 2 | B8: =VLOOKUP(A8,'Informe 2025'!$1:$1048576,2,FALSE) -> MARZO | C8: 25438930-7 | D8: =VLOOKUP(C8,ID!$1:$1048576,4,FALSE) -> 103965 | E8: =VLOOKUP(C8,ID!$1:$1048576,3,FALSE) -> YIRLEY YURANI | F8: =VLOOKUP(C8,ID!$1:$1048576,2,FALSE) -> HURTADO PRADO | G8: =VLOOKUP(D8,CORREOS!$A$2:$B$570,2,FALSE) -> YJHIDALGO@antayhoteles.cl | H8: =VLOOKUP(A8,'Informe 2025'!$A$5:$C$164,3,FALSE) -> Secuencia de servicio | I8: =VLOOKUP(H8,'Informe 2025'!$C$6:$M$166,11,FALSE) -> 2
A9: 2 | B9: =VLOOKUP(A9,'Informe 2025'!$1:$1048576,2,FALSE) -> MARZO | C9: 17555090-9 | D9: =VLOOKUP(C9,ID!$1:$1048576,4,FALSE) -> 102642 | E9: =VLOOKUP(C9,ID!$1:$1048576,3,FALSE) -> JOSE LUIS | F9: =VLOOKUP(C9,ID!$1:$1048576,2,FALSE) -> JIMENEZ VILLALOBOS | G9: =VLOOKUP(D9,CORREOS!$A$2:$B$570,2,FALSE) -> JJVILLALOBOS@ANTAYHOTELES.CL | H9: =VLOOKUP(A9,'Informe 2025'!$A$5:$C$164,3,FALSE) -> Secuencia de servicio | I9: =VLOOKUP(H9,'Informe 2025'!$C$6:$M$166,11,FALSE) -> 2
A10: 2 | B10: =VLOOKUP(A10,'Informe 2025'!$1:$1048576,2,FALSE) -> MARZO | C10: 22538546-7 | D10: =VLOOKUP(C10,ID!$1:$1048576,4,FALSE) -> 102982 | E10: =VLOOKUP(C10,ID!$1:$1048576,3,FALSE) -> CELINA | F10: =VLOOKUP(C10,ID!$1:$1048576,2,FALSE) -> GOMEZ OJEDA | G10: =VLOOKUP(D10,CORREOS!$A$2:$B$570,2,FALSE) -> CGOJEDA@ANTAYHOTELES.CL | H10: =VLOOKUP(A10,'Informe 2025'!$A$5:$C$164,3,FALSE) -> Secuencia de servicio | I10: =VLOOKUP(H10,'Informe 2025'!$C$6:$M$166,11,FALSE) -> 2
A11: 2 | B11: =VLOOKUP(A11,'Informe 2025'!$1:$1048576,2,FALSE) -> MARZO | C11: 19494811-5 | D11: =VLOOKUP(C11,ID!$1:$1048576,4,FALSE) -> 103457 | E11: =VLOOKUP(C11,ID!$1:$1048576,3,FALSE) -> MARCELO ORLANDO | F11: =VLOOKUP(C11,ID!$1:$1048576,2,FALSE) -> ARELLANO TARQUI | G11: =VLOOKUP(D11,CORREOS!$A$2:$B$570,2,FALSE) -> MARELLANO@ANTAYHOTELES.CL | H11: =VLOOKUP(A11,'Informe 2025'!$A$5:$C$164,3,FALSE) -> Secuencia de servicio | I11: =VLOOKUP(H11,'Informe 2025'!$C$6:$M$166,11,FALSE) -> 2
A12: 3 | B12: =VLOOKUP(A12,'Informe 2025'!$1:$1048576,2,FALSE) -> MARZO | C12: 21353679-6 | D12: =VLOOKUP(C12,ID!$1:$1048576,4,FALSE) -> 103252 | E12: =VLOOKUP(C12,ID!$1:$1048576,3,FALSE) -> DIEGO ADRIAN | F12: =VLOOKUP(C12,ID!$1:$1048576,2,FALSE) -> BARREAU FLORES | G12: =VLOOKUP(D12,CORREOS!$A$2:$B$570,2,FALSE) -> DBARREAU@antayhoteles.cl | H12: =VLOOKUP(A12,'Informe 2025'!$A$5:$C$164,3,FALSE) -> Introducción al mundo del vino | I12: =VLOOKUP(H12,'Informe 2025'!$C$6:$M$166,11,FALSE) -> 2
A13: 3 | B13: =VLOOKUP(A13,'Informe 2025'!$1:$1048576,2,FALSE) -> MARZO | C13: 25438930-7 | D13: =VLOOKUP(C13,ID!$1:$1048576,4,FALSE) -> 103965 | E13: =VLOOKUP(C13,ID!$1:$1048576,3,FALSE) -> YIRLEY YURANI | F13: =VLOOKUP(C13,ID!$1:$1048576,2,FALSE) -> HURTADO PRADO | G13: =VLOOKUP(D13,CORREOS!$A$2:$B$570,2,FALSE) -> YJHIDALGO@antayhoteles.cl | H13: =VLOOKUP(A13,'Informe 2025'!$A$5:$C$164,3,FALSE) -> Introducción al mundo del vino | I13: =VLOOKUP(H13,'Informe 2025'!$C$6:$M$166,11,FALSE) -> 2
A14: 3 | B14: =VLOOKUP(A14,'Informe 2025'!$1:$1048576,2,FALSE) -> MARZO | C14: 17555090-9 | D14: =VLOOKUP(C14,ID!$1:$1048576,4,FALSE) -> 102642 | E14: =VLOOKUP(C14,ID!$1:$1048576,3,FALSE) -> JOSE LUIS | F14: =VLOOKUP(C14,ID!$1:$1048576,2,FALSE) -> JIMENEZ VILLALOBOS | G14: =VLOOKUP(D14,CORREOS!$A$2:$B$570,2,FALSE) -> JJVILLALOBOS@ANTAYHOTELES.CL | H14: =VLOOKUP(A14,'Informe 2025'!$A$5:$C$164,3,FALSE) -> Introducción al mundo del vino | I14: =VLOOKUP(H14,'Informe 2025'!$C$6:$M$166,11,FALSE) -> 2
A15: 3 | B15: =VLOOKUP(A15,'Informe 2025'!$1:$1048576,2,FALSE) -> MARZO | C15: 22538546-7 | D15: =VLOOKUP(C15,ID!$1:$1048576,4,FALSE) -> 102982 | E15: =VLOOKUP(C15,ID!$1:$1048576,3,FALSE) -> CELINA | F15: =VLOOKUP(C15,ID!$1:$1048576,2,FALSE) -> GOMEZ OJEDA | G15: =VLOOKUP(D15,CORREOS!$A$2:$B$570,2,FALSE) -> CGOJEDA@ANTAYHOTELES.CL | H15: =VLOOKUP(A15,'Informe 2025'!$A$5:$C$164,3,FALSE) -> Introducción al mundo del vino | I15: =VLOOKUP(H15,'Informe 2025'!$C$6:$M$166,11,FALSE) -> 2
A16: 3 | B16: =VLOOKUP(A16,'Informe 2025'!$1:$1048576,2,FALSE) -> MARZO | C16: 19494811-5 | D16: =VLOOKUP(C16,ID!$1:$1048576,4,FALSE) -> 103457 | E16: =VLOOKUP(C16,ID!$1:$1048576,3,FALSE) -> MARCELO ORLANDO | F16: =VLOOKUP(C16,ID!$1:$1048576,2,FALSE) -> ARELLANO TARQUI | G16: =VLOOKUP(D16,CORREOS!$A$2:$B$570,2,FALSE) -> MARELLANO@ANTAYHOTELES.CL | H16: =VLOOKUP(A16,'Informe 2025'!$A$5:$C$164,3,FALSE) -> Introducción al mundo del vino | I16: =VLOOKUP(H16,'Informe 2025'!$C$6:$M$166,11,FALSE) -> 2
... A105: 9 | B105: =VLOOKUP(A105,'Informe 2025'!$1:$1048576,2,FALSE) -> MARZO | C105: 15007775-3 | D105: =VLOOKUP(C105,ID!$1:$1048576,4,FALSE) -> 101892 | E105: =VLOOKUP(C105,ID!$1:$1048576,3,FALSE) -> ALEJANDRO LUIS | F105: =VLOOKUP(C105,ID!$1:$1048576,2,FALSE) -> SOLIS AGUIRRE | G105: =VLOOKUP(D105,CORREOS!$A$2:$B$570,2,FALSE) -> ASOLIS@ANTAYHOTELES.CL | H105: =VLOOKUP(A105,'Informe 2025'!$A$5:$C$164,3,FALSE) -> Cata de Vinos | I105: =VLOOKUP(H105,'Informe 2025'!$C$6:$M$166,11,FALSE) -> 1.5
A106: 10 | B106: =VLOOKUP(A106,'Informe 2025'!$1:$1048576,2,FALSE) -> ABRIL | D106: =VLOOKUP(C106,ID!$1:$1048576,4,FALSE) -> #N/A | E106: =VLOOKUP(C106,ID!$1:$1048576,3,FALSE) -> #N/A | F106: =VLOOKUP(C106,ID!$1:$1048576,2,FALSE) -> #N/A | G106: =VLOOKUP(D106,CORREOS!$A$2:$B$570,2,FALSE) -> #N/A | H106: =VLOOKUP(A106,'Informe 2025'!$A$5:$C$164,3,FALSE) -> Escuela CCTV | I106: =VLOOKUP(H106,'Informe 2025'!$C$6:$M$166,11,FALSE) -> 80
A107: 10 | B107: =VLOOKUP(A107,'Informe 2025'!$1:$1048576,2,FALSE) -> ABRIL | D107: =VLOOKUP(C107,ID!$1:$1048576,4,FALSE) -> #N/A | E107: =VLOOKUP(C107,ID!$1:$1048576,3,FALSE) -> #N/A | F107: =VLOOKUP(C107,ID!$1:$1048576,2,FALSE) -> #N/A | G107: =VLOOKUP(D107,CORREOS!$A$2:$B$570,2,FALSE) -> #N/A | H107: =VLOOKUP(A107,'Informe 2025'!$A$5:$C$164,3,FALSE) -> Escuela CCTV | I107: =VLOOKUP(H107,'Informe 2025'!$C$6:$M$166,11,FALSE) -> 80
A108: 10 | B108: =VLOOKUP(A108,'Informe 2025'!$1:$1048576,2,FALSE) -> ABRIL | D108: =VLOOKUP(C108,ID!$1:$1048576,4,FALSE) -> #N/A | E108: =VLOOKUP(C108,ID!$1:$1048576,3,FALSE) -> #N/A | F108: =VLOOKUP(C108,ID!$1:$1048576,2,FALSE) -> #N/A | G108: =VLOOKUP(D108,CORREOS!$A$2:$B$570,2,FALSE) -> #N/A | H108: =VLOOKUP(A108,'Informe 2025'!$A$5:$C$164,3,FALSE) -> Escuela CCTV | I108: =VLOOKUP(H108,'Informe 2025'!$C$6:$M$166,11,FALSE) -> 80
A109: 11 | B109: =VLOOKUP(A109,'Informe 2025'!$1:$1048576,2,FALSE) -> ABRIL | C109: 21353679-6 | D109: =VLOOKUP(C109,ID!$1:$1048576,4,FALSE) -> 103252 | E109: =VLOOKUP(C109,ID!$1:$1048576,3,FALSE) -> DIEGO ADRIAN | F109: =VLOOKUP(C109,ID!$1:$1048576,2,FALSE) -> BARREAU FLORES | G109: =VLOOKUP(D109,CORREOS!$A$2:$B$570,2,FALSE) -> DBARREAU@antayhoteles.cl | H109: =VLOOKUP(A109,'Informe 2025'!$A$5:$C$164,3,FALSE) -> Formación AA&BB | I109: =VLOOKUP(H109,'Informe 2025'!$C$6:$M$166,11,FALSE) -> 2
A110: 11 | B110: =VLOOKUP(A110,'Informe 2025'!$1:$1048576,2,FALSE) -> ABRIL | C110: 19494811-5 | D110: =VLOOKUP(C110,ID!$1:$1048576,4,FALSE) -> 103457 | E110: =VLOOKUP(C110,ID!$1:$1048576,3,FALSE) -> MARCELO ORLANDO | F110: =VLOOKUP(C110,ID!$1:$1048576,2,FALSE) -> ARELLANO TARQUI | G110: =VLOOKUP(D110,CORREOS!$A$2:$B$570,2,FALSE) -> MARELLANO@ANTAYHOTELES.CL | H110: =VLOOKUP(A110,'Informe 2025'!$A$5:$C$164,3,FALSE) -> Formación AA&BB | I110: =VLOOKUP(H110,'Informe 2025'!$C$6:$M$166,11,FALSE) -> 2
A111: 11 | B111: =VLOOKUP(A111,'Informe 2025'!$1:$1048576,2,FALSE) -> ABRIL | C111: 21772827-4 | D111: =VLOOKUP(C111,ID!$1:$1048576,4,FALSE) -> 103189 | E111: =VLOOKUP(C111,ID!$1:$1048576,3,FALSE) -> ISIDORA MONSERRATH | F111: =VLOOKUP(C111,ID!$1:$1048576,2,FALSE) -> ASCENCIO MARTINEZ | G111: =VLOOKUP(D111,CORREOS!$A$2:$B$570,2,FALSE) -> IASCENCIO@ANTAYHOTELES.CL | H111: =VLOOKUP(A111,'Informe 2025'!$A$5:$C$164,3,FALSE) -> Formación AA&BB | I111: =VLOOKUP(H111,'Informe 2025'!$C$6:$M$166,11,FALSE) -> 2
A112: 11 | B112: =VLOOKUP(A112,'Informe 2025'!$1:$1048576,2,FALSE) -> ABRIL | C112: 21413200-1 | D112: =VLOOKUP(C112,ID!$1:$1048576,4,FALSE) -> 104068 | E112: =VLOOKUP(C112,ID!$1:$1048576,3,FALSE) -> BRANDON NICOLAS | F112: =VLOOKUP(C112,ID!$1:$1048576,2,FALSE) -> GOMEZ LOBOS | G112: =VLOOKUP(D112,CORREOS!$A$2:$B$570,2,FALSE) -> BGLOBOS@ANTAYHOTELES.CL | H112: =VLOOKUP(A112,'Informe 2025'!$A$5:$C$164,3,FALSE) -> Formación AA&BB | I112: =VLOOKUP(H112,'Informe 2025'!$C$6:$M$166,11,FALSE) -> 2
A113: 11 | B113: =VLOOKUP(A113,'Informe 2025'!$1:$1048576,2,FALSE) -> ABRIL | C113: 22160906-9 | D113: =VLOOKUP(C113,ID!$1:$1048576,4,FALSE) -> 103895 | E113: =VLOOKUP(C113,ID!$1:$1048576,3,FALSE) -> VICENTE ALONSO | F113: =VLOOKUP(C113,ID!$1:$1048576,2,FALSE) -> ZUMARAN JORQUERA | G113: =VLOOKUP(D113,CORREOS!$A$2:$B$570,2,FALSE) -> VZUMARAN@ANTAYHOTELES.CL | H113: =VLOOKUP(A113,'Informe 2025'!$A$5:$C$164,3,FALSE) -> Formación AA&BB | I113: =VLOOKUP(H113,'Informe 2025'!$C$6:$M$166,11,FALSE) -> 2
A114: 12 | B114: =VLOOKUP(A114,'Informe 2025'!$1:$1048576,2,FALSE) -> ABRIL | C114: 20846592-9 | D114: =VLOOKUP(C114,ID!$1:$1048576,4,FALSE) -> 102849 | E114: =VLOOKUP(C114,ID!$1:$1048576,3,FALSE) -> CRISTOBAL HUMBERTO | F114: =VLOOKUP(C114,ID!$1:$1048576,2,FALSE) -> CONDORI CARVAJAL | G114: =VLOOKUP(D114,CORREOS!$A$2:$B$570,2,FALSE) -> CCONDORI@ANTAYHOTELES.CL | H114: =VLOOKUP(A114,'Informe 2025'!$A$5:$C$164,3,FALSE) -> Tutor "capcula de seguridad" | I114: =VLOOKUP(H114,'Informe 2025'!$C$6:$M$166,11,FALSE) -> 2
A115: 12 | B115: =VLOOKUP(A115,'Informe 2025'!$1:$1048576,2,FALSE) -> ABRIL | C115: 21501012-0 | D115: =VLOOKUP(C115,ID!$1:$1048576,4,FALSE) -> 103010 | E115: =VLOOKUP(C115,ID!$1:$1048576,3,FALSE) -> FERNANDO | F115: =VLOOKUP(C115,ID!$1:$1048576,2,FALSE) -> GONZALEZ OROZCO | G115: =VLOOKUP(D115,CORREOS!$A$2:$B$570,2,FALSE) -> FGOROZCO@ANTAYHOTELES.CL | H115: =VLOOKUP(A115,'Informe 2025'!$A$5:$C$164,3,FALSE) -> Tutor "capcula de seguridad" | I115: =VLOOKUP(H115,'Informe 2025'!$C$6:$M$166,11,FALSE) -> 2
A116: 12 | B116: =VLOOKUP(A116,'Informe 2025'!$1:$1048576,2,FALSE) -> ABRIL | C116: 19827553-0 | D116: =VLOOKUP(C116,ID!$1:$1048576,4,FALSE) -> 102996 | E116: =VLOOKUP(C116,ID!$1:$1048576,3,FALSE) -> CATALINA VICTORIA | F116: =VLOOKUP(C116,ID!$1:$1048576,2,FALSE) -> CABEZAS MENA | G116: =VLOOKUP(D116,CORREOS!$A$2:$B$570,2,FALSE) -> CCABEZAS@ANTAYHOTELES.CL | H116: =VLOOKUP(A116,'Informe 2025'!$A$5:$C$164,3,FALSE) -> Tutor "capcula de seguridad" | I116: =VLOOKUP(H116,'Informe 2025'!$C$6:$M$166,11,FALSE) -> 2
A117: 12 | B117: =VLOOKUP(A117,'Informe 2025'!$1:$1048576,2,FALSE) -> ABRIL | C117: 18599712-K | D117: =VLOOKUP(C117,ID!$1:$1048576,4,FALSE) -> 102795 | E117: =VLOOKUP(C117,ID!$1:$1048576,3,FALSE) -> CATALINA FRANCISCA | F117: =VLOOKUP(C117,ID!$1:$1048576,2,FALSE) -> CONTRERAS GONZALEZ | G117: =VLOOKUP(D117,CORREOS!$A$2:$B$570,2,FALSE) -> CCGONZALEZ@ANTAYHOTELES.CL | H117: =VLOOKUP(A117,'Informe 2025'!$A$5:$C$164,3,FALSE) -> Tutor "capcula de seguridad" | I117: =VLOOKUP(H117,'Informe 2025'!$C$6:$M$166,11,FALSE) -> 2
A118: 12 | B118: =VLOOKUP(A118,'Informe 2025'!$1:$1048576,2,FALSE) -> ABRIL | C118: 13006838-3 | D118: =VLOOKUP(C118,ID!$1:$1048576,4,FALSE) -> 102829 | E118: =VLOOKUP(C118,ID!$1:$1048576,3,FALSE) -> WILSON DENNIS | F118: =VLOOKUP(C118,ID!$1:$1048576,2,FALSE) -> CASTILLO PEREZ | G118: =VLOOKUP(D118,CORREOS!$A$2:$B$570,2,FALSE) -> WCASTILLO@CL.LUCKIA.COM | H118: =VLOOKUP(A118,'Informe 2025'!$A$5:$C$164,3,FALSE) -> Tutor "capcula de seguridad" | I118: =VLOOKUP(H118,'Informe 2025'!$C$6:$M$166,11,FALSE) -> 2
A119: 12 | B119: =VLOOKUP(A119,'Informe 2025'!$1:$1048576,2,FALSE) -> ABRIL | C119: 20348795-9 | D119: =VLOOKUP(C119,ID!$1:$1048576,4,FALSE) -> 102292 | E119: =VLOOKUP(C119,ID!$1:$1048576,3,FALSE) -> ESKARLETT YUBINZA | F119: =VLOOKUP(C119,ID!$1:$1048576,2,FALSE) -> ZULETA COLQUE | G119: =VLOOKUP(D119,CORREOS!$A$2:$B$570,2,FALSE) -> EZCOLQUE@CL.LUCKIA.COM | H119: =VLOOKUP(A119,'Informe 2025'!$A$5:$C$164,3,FALSE) -> Tutor "capcula de seguridad" | I119: =VLOOKUP(H119,'Informe 2025'!$C$6:$M$166,11,FALSE) -> 2
A120: 12 | B120: =VLOOKUP(A120,'Informe 2025'!$1:$1048576,2,FALSE) -> ABRIL | C120: 19868671-9 | D120: =VLOOKUP(C120,ID!$1:$1048576,4,FALSE) -> 102903 | E120: =VLOOKUP(C120,ID!$1:$1048576,3,FALSE) -> KEVIN MARCELO | F120: =VLOOKUP(C120,ID!$1:$1048576,2,FALSE) -> AROS CASTRO | G120: =VLOOKUP(D120,CORREOS!$A$2:$B$570,2,FALSE) -> KAROS@ANTAYHOTELES.CL | H120: =VLOOKUP(A120,'Informe 2025'!$A$5:$C$164,3,FALSE) -> Tutor "capcula de seguridad" | I120: =VLOOKUP(H120,'Informe 2025'!$C$6:$M$166,11,FALSE) -> 2
... A969: 75 | B969: =VLOOKUP(A969,'Informe 2025'!$1:$1048576,2,FALSE) -> SEPTIEMBRE | C969: 15009247-7 | D969: =VLOOKUP(C969,ID!$1:$1048576,4,FALSE) -> 104250 | E969: =VLOOKUP(C969,ID!$1:$1048576,3,FALSE) -> LUIS FELIPE | F969: =VLOOKUP(C969,ID!$1:$1048576,2,FALSE) -> ESPINOZA ESCOBAR | G969: =VLOOKUP(D969,CORREOS!$A$2:$B$570,2,FALSE) -> LESPINOZA@CL.LUCKIA.COM | H969: =VLOOKUP(A969,'Informe 2025'!$A$5:$C$164,3,FALSE) -> Lenguaje no Verbal | I969: =VLOOKUP(H969,'Informe 2025'!$C$6:$M$166,11,FALSE) -> 4
B970: =VLOOKUP(A970,'Informe 2025'!$1:$1048576,2,FALSE) -> #N/A | D970: =VLOOKUP(C970,ID!$1:$1048576,4,FALSE) -> #N/A | E970: =VLOOKUP(C970,ID!$1:$1048576,3,FALSE) -> #N/A | F970: =VLOOKUP(C970,ID!$1:$1048576,2,FALSE) -> #N/A | G970: =VLOOKUP(D970,CORREOS!$A$2:$B$570,2,FALSE) -> #N/A | H970: =VLOOKUP(A970,'Informe 2025'!$A$5:$C$164,3,FALSE) -> #N/A | I970: =VLOOKUP(H970,'Informe 2025'!$C$6:$M$166,11,FALSE) -> #N/A
B971: =VLOOKUP(A971,'Informe 2025'!$1:$1048576,2,FALSE) -> #N/A | D971: =VLOOKUP(C971,ID!$1:$1048576,4,FALSE) -> #N/A | E971: =VLOOKUP(C971,ID!$1:$1048576,3,FALSE) -> #N/A | F971: =VLOOKUP(C971,ID!$1:$1048576,2,FALSE) -> #N/A | G971: =VLOOKUP(D971,CORREOS!$A$2:$B$570,2,FALSE) -> #N/A | H971: =VLOOKUP(A971,'Informe 2025'!$A$5:$C$164,3,FALSE) -> #N/A | I971: =VLOOKUP(H971,'Informe 2025'!$C$6:$M$166,11,FALSE) -> #N/A
B972: =VLOOKUP(A972,'Informe 2025'!$1:$1048576,2,FALSE) -> #N/A | D972: =VLOOKUP(C972,ID!$1:$1048576,4,FALSE) -> #N/A | E972: =VLOOKUP(C972,ID!$1:$1048576,3,FALSE) -> #N/A | F972: =VLOOKUP(C972,ID!$1:$1048576,2,FALSE) -> #N/A | G972: =VLOOKUP(D972,CORREOS!$A$2:$B$570,2,FALSE) -> #N/A | H972: =VLOOKUP(A972,'Informe 2025'!$A$5:$C$164,3,FALSE) -> #N/A | I972: =VLOOKUP(H972,'Informe 2025'!$C$6:$M$166,11,FALSE) -> #N/A
B973: =VLOOKUP(A973,'Informe 2025'!$1:$1048576,2,FALSE) -> #N/A | D973: =VLOOKUP(C973,ID!$1:$1048576,4,FALSE) -> #N/A | E973: =VLOOKUP(C973,ID!$1:$1048576,3,FALSE) -> #N/A | F973: =VLOOKUP(C973,ID!$1:$1048576,2,FALSE) -> #N/A | G973: =VLOOKUP(D973,CORREOS!$A$2:$B$570,2,FALSE) -> #N/A | H973: =VLOOKUP(A973,'Informe 2025'!$A$5:$C$164,3,FALSE) -> #N/A | I973: =VLOOKUP(H973,'Informe 2025'!$C$6:$M$166,11,FALSE) -> #N/A
B974: =VLOOKUP(A974,'Informe 2025'!$1:$1048576,2,FALSE) -> #N/A | D974: =VLOOKUP(C974,ID!$1:$1048576,4,FALSE) -> #N/A | E974: =VLOOKUP(C974,ID!$1:$1048576,3,FALSE) -> #N/A | F974: =VLOOKUP(C974,ID!$1:$1048576,2,FALSE) -> #N/A | G974: =VLOOKUP(D974,CORREOS!$A$2:$B$570,2,FALSE) -> #N/A | H974: =VLOOKUP(A974,'Informe 2025'!$A$5:$C$164,3,FALSE) -> #N/A | I974: =VLOOKUP(H974,'Informe 2025'!$C$6:$M$166,11,FALSE) -> #N/A
B975: =VLOOKUP(A975,'Informe 2025'!$1:$1048576,2,FALSE) -> #N/A | D975: =VLOOKUP(C975,ID!$1:$1048576,4,FALSE) -> #N/A | E975: =VLOOKUP(C975,ID!$1:$1048576,3,FALSE) -> #N/A | F975: =VLOOKUP(C975,ID!$1:$1048576,2,FALSE) -> #N/A | G975: =VLOOKUP(D975,CORREOS!$A$2:$B$570,2,FALSE) -> #N/A | H975: =VLOOKUP(A975,'Informe 2025'!$A$5:$C$164,3,FALSE) -> #N/A | I975: =VLOOKUP(H975,'Informe 2025'!$C$6:$M$166,11,FALSE) -> #N/A
B976: =VLOOKUP(A976,'Informe 2025'!$1:$1048576,2,FALSE) -> #N/A | D976: =VLOOKUP(C976,ID!$1:$1048576,4,FALSE) -> #N/A | E976: =VLOOKUP(C976,ID!$1:$1048576,3,FALSE) -> #N/A | F976: =VLOOKUP(C976,ID!$1:$1048576,2,FALSE) -> #N/A | G976: =VLOOKUP(D976,CORREOS!$A$2:$B$570,2,FALSE) -> #N/A | H976: =VLOOKUP(A976,'Informe 2025'!$A$5:$C$164,3,FALSE) -> #N/A | I976: =VLOOKUP(H976,'Informe 2025'!$C$6:$M$166,11,FALSE) -> #N/A
...

Sheet Guía
A1: Lugar de impartición | B1: Presencial, Online o Virtual
A2: Área temática | B2: Negocio, Cliente, Cultura, Digital, Liderazgo
A3: Tipo de curso | B3: (Igual que área temática)
A4: Gerencia | B4: Perú, Croacia, Copiapó, Arica
A5: Coste total | B5: En euros

Sheet ID
A1: 20709555-9 | B1: ABARCA NUÑEZ | C1: FELIPE | D1: 102545
A2: 20705682-0 | B2: ACEVEDO ARRIAZA | C2: VICTOR | D2: 103032
A3: 20094052-0 | B3: ACUÑA PAEZ | C3: MITZY FERNANDA | D3: 102935
A4: 10471969-4 | B4: AEDO ROJAS | C4: ROSA ESTER | D4: 102879
A5: 21313485-K | B5: AGUILAR FERNANDEZ | C5: VALENTINA | D5: 103053
A6: 19494181-1 | B6: AGUILAR PINTO | C6: AMELIA PAZ | D6: 103499
A7: 19356863-7 | B7: AGUILERA BEYZAGA | C7: FRANCISCA MICHEL | D7: 101971
A8: 19493141-7 | B8: AGUILERA FUENTEALBA | C8: MAITTE CONSTANZA | D8: 102983
A9: 17556754-2 | B9: AGUILERA JIMENEZ | C9: BIANCA DANIELA | D9: 102317
A10: 23378201-7 | B10: AGUIRRE ESPINOZA | C10: FATIMA JUDITH | D10: 100348
A11: 19148985-3 | B11: AGUIRRE MEDINA | C11: DANIEL ROMUALDO | D11: 102834
A12: 19357338-K | B12: AHUMADA ROSSI | C12: CLAUDIA CAMILA | D12: 102871
... A347: 20348795-9 | B347: ZULETA COLQUE | C347: ESKARLETT YUBINZA | D347: 102292
A348: 12609907-K | B348: RODRIGUEZ VARGAS | C348: JESSICA | D348: 104072
A349: 17556754-2 | B349: AGUILERA JIMENEZ | C349: BIANCA DANIELA | D349: 102317
A350: 28444604-6 | B350: ALDUNATE MEDINA | C350: ROBERTO CARLOS | D350: 103814
A351: 20215964-8 | B351: ANTEZANA ARAYA | C351: THIARE ALEXANDRA | D351: 103394
A352: 21777103-K | B352: ARAYA FLORES | C352: VALENTINA PAZ | D352: 103796
A353: 22010904-6 | B353: ARAYA LORCA | C353: FERNANDA IGNACIA | D353: 103792
A354: 20546884-6 | B354: ASTUDILLO MUÑOZ | C354: ANAHI PAZ | D354: 102798
A355: 17829037-1 | B355: BAEZA COFRÉ | C355: JUAN MAYKOL LUIS | D355: 102197
A356: 18822721-K | B356: CASTILLO VARAS | C356: ARANZA ALEJANDRA | D356: 103810
A357: 8843648-2 | B357: CATALAN ROSALES | C357: BERNARDITA | D357: 102786
A358: 17772748-2 | B358: GODOY PEÑA | C358: DIEGO ANTONIO | D358: 100753
A359: 20767515-6 | B359: GOMEZ YAÑEZ | C359: DIEGO GUSTAVO | D359: 103793
A360: 9904862-K | B360: GONZALEZ GONZALEZ | C360: MARIA ESTHER | D360: 101791
... A595: 16469358-9 | B595: FALLARIS VILLEGAS | C595: KAREN ROXANA | D595: 104311
A596: 20473731-2 | B596: MARTINEZ BRAVO | C596: MICHELLE | D596: 104360

Sheet CORREOS
A2: 102545 | B2: FABARCA@ANTAYHOTELES.CL
A3: 103032 | B3: VAARRIAZA@ANTAYHOTELES.CL
A4: 102935 | B4: MACUNA@ANTAYHOTELES.CL
A5: 102879 | B5: RAEDO@ANTAYHOTELES.CL
A6: 102292 | B6: EZCOLQUE@CL.LUCKIA.COM
A7: 101672 | B7: CAMILANICOLE.YAVAR@CL.LUCKIA.COM
A8: 101971 | B8: FAGUILERA@ANTAYHOTELES.CL
A9: 102983 | B9: MAFUENTEALBA@ANTAYHOTELES.CL
A10: 103256 | B10: SAALVAREZ@CL.LUCKIA.COM
A11: 101333 | B11: ENRIQUEJAVIER.YANEZ@CL.LUCKIA.COM
A12: 102834 | B12: DAGUIRRE@ANTAYHOTELES.CL
A13: 101682 | B13: ALVAROGUILLERMO.VIDAL@CL.LUCKIA.COM
... A570: 104311 | B570: KFALLARIS@ANTAYHOTELES.CL
A571: 104360 | B571: MMBRAVO@CL.LUCKIA.COM

Sheet RESUMEN
